2020-11-16 09:31:02,844 INFO: IpManager startup [in /volumec/python_programe/python-exercise/ipmanager/app/__init__.py:32]
2020-11-16 09:31:50,233 INFO: IpManager startup [in /volumec/python_programe/python-exercise/ipmanager/app/__init__.py:32]
2020-11-16 09:32:10,119 ERROR: Exception on /user_add [POST] [in /volumec/python_programe/python-exercise/ipmanager/venv/lib64/python3.6/site-packages/flask/app.py:1892]
Traceback (most recent call last):
  File "/volumec/python_programe/python-exercise/ipmanager/venv/lib64/python3.6/site-packages/sqlalchemy/engine/base.py", line 1277, in _execute_context
    cursor, statement, parameters, context
  File "/volumec/python_programe/python-exercise/ipmanager/venv/lib64/python3.6/site-packages/sqlalchemy/engine/default.py", line 593, in do_execute
    cursor.execute(statement, parameters)
sqlite3.IntegrityError: column username is not unique

The above exception was the direct cause of the following exception:

Traceback (most recent call last):
  File "/volumec/python_programe/python-exercise/ipmanager/venv/lib64/python3.6/site-packages/flask/app.py", line 2447, in wsgi_app
    response = self.full_dispatch_request()
  File "/volumec/python_programe/python-exercise/ipmanager/venv/lib64/python3.6/site-packages/flask/app.py", line 1952, in full_dispatch_request
    rv = self.handle_user_exception(e)
  File "/volumec/python_programe/python-exercise/ipmanager/venv/lib64/python3.6/site-packages/flask/app.py", line 1821, in handle_user_exception
    reraise(exc_type, exc_value, tb)
  File "/volumec/python_programe/python-exercise/ipmanager/venv/lib64/python3.6/site-packages/flask/_compat.py", line 39, in reraise
    raise value
  File "/volumec/python_programe/python-exercise/ipmanager/venv/lib64/python3.6/site-packages/flask/app.py", line 1950, in full_dispatch_request
    rv = self.dispatch_request()
  File "/volumec/python_programe/python-exercise/ipmanager/venv/lib64/python3.6/site-packages/flask/app.py", line 1936, in dispatch_request
    return self.view_functions[rule.endpoint](**req.view_args)
  File "/volumec/python_programe/python-exercise/ipmanager/venv/lib64/python3.6/site-packages/flask_login/utils.py", line 272, in decorated_view
    return func(*args, **kwargs)
  File "/volumec/python_programe/python-exercise/ipmanager/app/routes.py", line 79, in user_add
    db.session.commit()
  File "/volumec/python_programe/python-exercise/ipmanager/venv/lib64/python3.6/site-packages/sqlalchemy/orm/scoping.py", line 163, in do
    return getattr(self.registry(), name)(*args, **kwargs)
  File "/volumec/python_programe/python-exercise/ipmanager/venv/lib64/python3.6/site-packages/sqlalchemy/orm/session.py", line 1042, in commit
    self.transaction.commit()
  File "/volumec/python_programe/python-exercise/ipmanager/venv/lib64/python3.6/site-packages/sqlalchemy/orm/session.py", line 504, in commit
    self._prepare_impl()
  File "/volumec/python_programe/python-exercise/ipmanager/venv/lib64/python3.6/site-packages/sqlalchemy/orm/session.py", line 483, in _prepare_impl
    self.session.flush()
  File "/volumec/python_programe/python-exercise/ipmanager/venv/lib64/python3.6/site-packages/sqlalchemy/orm/session.py", line 2536, in flush
    self._flush(objects)
  File "/volumec/python_programe/python-exercise/ipmanager/venv/lib64/python3.6/site-packages/sqlalchemy/orm/session.py", line 2678, in _flush
    transaction.rollback(_capture_exception=True)
  File "/volumec/python_programe/python-exercise/ipmanager/venv/lib64/python3.6/site-packages/sqlalchemy/util/langhelpers.py", line 70, in __exit__
    with_traceback=exc_tb,
  File "/volumec/python_programe/python-exercise/ipmanager/venv/lib64/python3.6/site-packages/sqlalchemy/util/compat.py", line 182, in raise_
    raise exception
  File "/volumec/python_programe/python-exercise/ipmanager/venv/lib64/python3.6/site-packages/sqlalchemy/orm/session.py", line 2638, in _flush
    flush_context.execute()
  File "/volumec/python_programe/python-exercise/ipmanager/venv/lib64/python3.6/site-packages/sqlalchemy/orm/unitofwork.py", line 422, in execute
    rec.execute(self)
  File "/volumec/python_programe/python-exercise/ipmanager/venv/lib64/python3.6/site-packages/sqlalchemy/orm/unitofwork.py", line 589, in execute
    uow,
  File "/volumec/python_programe/python-exercise/ipmanager/venv/lib64/python3.6/site-packages/sqlalchemy/orm/persistence.py", line 245, in save_obj
    insert,
  File "/volumec/python_programe/python-exercise/ipmanager/venv/lib64/python3.6/site-packages/sqlalchemy/orm/persistence.py", line 1136, in _emit_insert_statements
    statement, params
  File "/volumec/python_programe/python-exercise/ipmanager/venv/lib64/python3.6/site-packages/sqlalchemy/engine/base.py", line 1011, in execute
    return meth(self, multiparams, params)
  File "/volumec/python_programe/python-exercise/ipmanager/venv/lib64/python3.6/site-packages/sqlalchemy/sql/elements.py", line 298, in _execute_on_connection
    return connection._execute_clauseelement(self, multiparams, params)
  File "/volumec/python_programe/python-exercise/ipmanager/venv/lib64/python3.6/site-packages/sqlalchemy/engine/base.py", line 1130, in _execute_clauseelement
    distilled_params,
  File "/volumec/python_programe/python-exercise/ipmanager/venv/lib64/python3.6/site-packages/sqlalchemy/engine/base.py", line 1317, in _execute_context
    e, statement, parameters, cursor, context
  File "/volumec/python_programe/python-exercise/ipmanager/venv/lib64/python3.6/site-packages/sqlalchemy/engine/base.py", line 1511, in _handle_dbapi_exception
    sqlalchemy_exception, with_traceback=exc_info[2], from_=e
  File "/volumec/python_programe/python-exercise/ipmanager/venv/lib64/python3.6/site-packages/sqlalchemy/util/compat.py", line 182, in raise_
    raise exception
  File "/volumec/python_programe/python-exercise/ipmanager/venv/lib64/python3.6/site-packages/sqlalchemy/engine/base.py", line 1277, in _execute_context
    cursor, statement, parameters, context
  File "/volumec/python_programe/python-exercise/ipmanager/venv/lib64/python3.6/site-packages/sqlalchemy/engine/default.py", line 593, in do_execute
    cursor.execute(statement, parameters)
sqlalchemy.exc.IntegrityError: (sqlite3.IntegrityError) column username is not unique
[SQL: INSERT INTO user (username, email, password_hash, role) VALUES (?, ?, ?, ?)]
[parameters: ('joker', None, 'pbkdf2:sha256:150000$rkOxuK4B$4d80663c97a51d370d09f91986c35530a64038abad8407590599b36aae5b2f35', 'general user')]
(Background on this error at: http://sqlalche.me/e/13/gkpj)
2020-11-16 09:35:37,462 INFO: IpManager startup [in /volumec/python_programe/python-exercise/ipmanager/app/__init__.py:32]
2020-11-16 09:36:58,727 INFO: IpManager startup [in /volumec/python_programe/python-exercise/ipmanager/app/__init__.py:32]
