2020-11-16 09:48:41,669 ERROR: Exception on /updateIpinfo [POST] [in /volumec/python_programe/python-exercise/ipmanager/venv/lib64/python3.6/site-packages/flask/app.py:1892]
Traceback (most recent call last):
  File "/volumec/python_programe/python-exercise/ipmanager/venv/lib64/python3.6/site-packages/sqlalchemy/engine/base.py", line 1277, in _execute_context
    cursor, statement, parameters, context
  File "/volumec/python_programe/python-exercise/ipmanager/venv/lib64/python3.6/site-packages/sqlalchemy/engine/default.py", line 593, in do_execute
    cursor.execute(statement, parameters)
sqlite3.IntegrityError: column ip is not unique

The above exception was the direct cause of the following exception:

Traceback (most recent call last):
  File "/volumec/python_programe/python-exercise/ipmanager/venv/lib64/python3.6/site-packages/flask/app.py", line 2447, in wsgi_app
    response = self.full_dispatch_request()
  File "/volumec/python_programe/python-exercise/ipmanager/venv/lib64/python3.6/site-packages/flask/app.py", line 1952, in full_dispatch_request
    rv = self.handle_user_exception(e)
  File "/volumec/python_programe/python-exercise/ipmanager/venv/lib64/python3.6/site-packages/flask/app.py", line 1821, in handle_user_exception
    reraise(exc_type, exc_value, tb)
  File "/volumec/python_programe/python-exercise/ipmanager/venv/lib64/python3.6/site-packages/flask/_compat.py", line 39, in reraise
    raise value
  File "/volumec/python_programe/python-exercise/ipmanager/venv/lib64/python3.6/site-packages/flask/app.py", line 1950, in full_dispatch_request
    rv = self.dispatch_request()
  File "/volumec/python_programe/python-exercise/ipmanager/venv/lib64/python3.6/site-packages/flask/app.py", line 1936, in dispatch_request
    return self.view_functions[rule.endpoint](**req.view_args)
  File "/volumec/python_programe/python-exercise/ipmanager/venv/lib64/python3.6/site-packages/flask_login/utils.py", line 272, in decorated_view
    return func(*args, **kwargs)
  File "/volumec/python_programe/python-exercise/ipmanager/app/routes.py", line 176, in updateIpinfo
    new_ipinfo = Ipinfo.query.get(id)
  File "/volumec/python_programe/python-exercise/ipmanager/venv/lib64/python3.6/site-packages/sqlalchemy/orm/scoping.py", line 163, in do
    return getattr(self.registry(), name)(*args, **kwargs)
  File "/volumec/python_programe/python-exercise/ipmanager/venv/lib64/python3.6/site-packages/sqlalchemy/orm/session.py", line 1042, in commit
    self.transaction.commit()
  File "/volumec/python_programe/python-exercise/ipmanager/venv/lib64/python3.6/site-packages/sqlalchemy/orm/session.py", line 504, in commit
    self._prepare_impl()
  File "/volumec/python_programe/python-exercise/ipmanager/venv/lib64/python3.6/site-packages/sqlalchemy/orm/session.py", line 483, in _prepare_impl
    self.session.flush()
  File "/volumec/python_programe/python-exercise/ipmanager/venv/lib64/python3.6/site-packages/sqlalchemy/orm/session.py", line 2536, in flush
    self._flush(objects)
  File "/volumec/python_programe/python-exercise/ipmanager/venv/lib64/python3.6/site-packages/sqlalchemy/orm/session.py", line 2678, in _flush
    transaction.rollback(_capture_exception=True)
  File "/volumec/python_programe/python-exercise/ipmanager/venv/lib64/python3.6/site-packages/sqlalchemy/util/langhelpers.py", line 70, in __exit__
    with_traceback=exc_tb,
  File "/volumec/python_programe/python-exercise/ipmanager/venv/lib64/python3.6/site-packages/sqlalchemy/util/compat.py", line 182, in raise_
    raise exception
  File "/volumec/python_programe/python-exercise/ipmanager/venv/lib64/python3.6/site-packages/sqlalchemy/orm/session.py", line 2638, in _flush
    flush_context.execute()
  File "/volumec/python_programe/python-exercise/ipmanager/venv/lib64/python3.6/site-packages/sqlalchemy/orm/unitofwork.py", line 422, in execute
    rec.execute(self)
  File "/volumec/python_programe/python-exercise/ipmanager/venv/lib64/python3.6/site-packages/sqlalchemy/orm/unitofwork.py", line 589, in execute
    uow,
  File "/volumec/python_programe/python-exercise/ipmanager/venv/lib64/python3.6/site-packages/sqlalchemy/orm/persistence.py", line 236, in save_obj
    update,
  File "/volumec/python_programe/python-exercise/ipmanager/venv/lib64/python3.6/site-packages/sqlalchemy/orm/persistence.py", line 995, in _emit_update_statements
    statement, multiparams
  File "/volumec/python_programe/python-exercise/ipmanager/venv/lib64/python3.6/site-packages/sqlalchemy/engine/base.py", line 1011, in execute
    return meth(self, multiparams, params)
  File "/volumec/python_programe/python-exercise/ipmanager/venv/lib64/python3.6/site-packages/sqlalchemy/sql/elements.py", line 298, in _execute_on_connection
    return connection._execute_clauseelement(self, multiparams, params)
  File "/volumec/python_programe/python-exercise/ipmanager/venv/lib64/python3.6/site-packages/sqlalchemy/engine/base.py", line 1130, in _execute_clauseelement
    distilled_params,
  File "/volumec/python_programe/python-exercise/ipmanager/venv/lib64/python3.6/site-packages/sqlalchemy/engine/base.py", line 1317, in _execute_context
    e, statement, parameters, cursor, context
  File "/volumec/python_programe/python-exercise/ipmanager/venv/lib64/python3.6/site-packages/sqlalchemy/engine/base.py", line 1511, in _handle_dbapi_exception
    sqlalchemy_exception, with_traceback=exc_info[2], from_=e
  File "/volumec/python_programe/python-exercise/ipmanager/venv/lib64/python3.6/site-packages/sqlalchemy/util/compat.py", line 182, in raise_
    raise exception
  File "/volumec/python_programe/python-exercise/ipmanager/venv/lib64/python3.6/site-packages/sqlalchemy/engine/base.py", line 1277, in _execute_context
    cursor, statement, parameters, context
  File "/volumec/python_programe/python-exercise/ipmanager/venv/lib64/python3.6/site-packages/sqlalchemy/engine/default.py", line 593, in do_execute
    cursor.execute(statement, parameters)
sqlalchemy.exc.IntegrityError: (sqlite3.IntegrityError) column ip is not unique
[SQL: UPDATE ipinfo SET ip=? WHERE ipinfo.id = ?]
[parameters: ('192.168.1.1', 12)]
(Background on this error at: http://sqlalche.me/e/13/gkpj)
2020-11-16 09:55:33,789 INFO: IpManager startup [in /volumec/python_programe/python-exercise/ipmanager/app/__init__.py:32]
2020-11-16 10:01:31,771 INFO: IpManager startup [in /volumec/python_programe/python-exercise/ipmanager/app/__init__.py:32]
2020-11-16 10:03:09,362 INFO: IpManager startup [in /volumec/python_programe/python-exercise/ipmanager/app/__init__.py:32]
2020-11-16 10:19:19,680 INFO: IpManager startup [in /volumec/python_programe/python-exercise/ipmanager/app/__init__.py:32]
2020-11-16 10:19:31,476 INFO: IpManager startup [in /volumec/python_programe/python-exercise/ipmanager/app/__init__.py:32]
2020-11-17 10:41:18,767 INFO: IpManager startup [in /volumec/python_programe/python-exercise/ipmanager/app/__init__.py:32]
2020-11-20 16:25:45,936 INFO: IpManager startup [in /volumec/python_programe/python-exercise/ipmanager/app/__init__.py:32]
2020-11-20 16:27:27,417 INFO: IpManager startup [in /volumec/python_programe/python-exercise/ipmanager/app/__init__.py:32]
2020-12-17 14:14:41,626 INFO: IpManager startup [in /volumec/python_programe/python-exercise/ipmanager/app/__init__.py:32]
