2020-11-12 16:58:22,324 ERROR: Exception on /index [GET] [in /volumec/python_programe/python-exercise/ipmanager/venv/lib64/python3.6/site-packages/flask/app.py:1892]
Traceback (most recent call last):
  File "/volumec/python_programe/python-exercise/ipmanager/venv/lib64/python3.6/site-packages/flask/app.py", line 2447, in wsgi_app
    response = self.full_dispatch_request()
  File "/volumec/python_programe/python-exercise/ipmanager/venv/lib64/python3.6/site-packages/flask/app.py", line 1952, in full_dispatch_request
    rv = self.handle_user_exception(e)
  File "/volumec/python_programe/python-exercise/ipmanager/venv/lib64/python3.6/site-packages/flask/app.py", line 1821, in handle_user_exception
    reraise(exc_type, exc_value, tb)
  File "/volumec/python_programe/python-exercise/ipmanager/venv/lib64/python3.6/site-packages/flask/_compat.py", line 39, in reraise
    raise value
  File "/volumec/python_programe/python-exercise/ipmanager/venv/lib64/python3.6/site-packages/flask/app.py", line 1950, in full_dispatch_request
    rv = self.dispatch_request()
  File "/volumec/python_programe/python-exercise/ipmanager/venv/lib64/python3.6/site-packages/flask/app.py", line 1936, in dispatch_request
    return self.view_functions[rule.endpoint](**req.view_args)
  File "/volumec/python_programe/python-exercise/ipmanager/venv/lib64/python3.6/site-packages/flask_login/utils.py", line 272, in decorated_view
    return func(*args, **kwargs)
  File "/volumec/python_programe/python-exercise/ipmanager/app/routes.py", line 30, in index
    prev_url=prev_url)
  File "/volumec/python_programe/python-exercise/ipmanager/venv/lib64/python3.6/site-packages/flask/templating.py", line 140, in render_template
    ctx.app,
  File "/volumec/python_programe/python-exercise/ipmanager/venv/lib64/python3.6/site-packages/flask/templating.py", line 120, in _render
    rv = template.render(context)
  File "/volumec/python_programe/python-exercise/ipmanager/venv/lib64/python3.6/site-packages/jinja2/environment.py", line 1090, in render
    self.environment.handle_exception()
  File "/volumec/python_programe/python-exercise/ipmanager/venv/lib64/python3.6/site-packages/jinja2/environment.py", line 832, in handle_exception
    reraise(*rewrite_traceback_stack(source=source))
  File "/volumec/python_programe/python-exercise/ipmanager/venv/lib64/python3.6/site-packages/jinja2/_compat.py", line 28, in reraise
    raise value.with_traceback(tb)
  File "/volumec/python_programe/python-exercise/ipmanager/app/templates/index.html", line 1, in top-level template code
    {% extends "base.html" %}
  File "/volumec/python_programe/python-exercise/ipmanager/app/templates/base.html", line 1, in top-level template code
    {% extends 'bootstrap/base.html' %}
  File "/volumec/python_programe/python-exercise/ipmanager/venv/lib64/python3.6/site-packages/flask_bootstrap/templates/bootstrap/base.html", line 1, in top-level template code
    {% block doc -%}
  File "/volumec/python_programe/python-exercise/ipmanager/venv/lib64/python3.6/site-packages/flask_bootstrap/templates/bootstrap/base.html", line 4, in block "doc"
    {%- block html %}
  File "/volumec/python_programe/python-exercise/ipmanager/venv/lib64/python3.6/site-packages/flask_bootstrap/templates/bootstrap/base.html", line 20, in block "html"
    {% block body -%}
  File "/volumec/python_programe/python-exercise/ipmanager/venv/lib64/python3.6/site-packages/flask_bootstrap/templates/bootstrap/base.html", line 21, in block "body"
    {% block navbar %}
  File "/volumec/python_programe/python-exercise/ipmanager/app/templates/base.html", line 31, in block "navbar"
    <li><a href="{{ url_for('user_add') }}">用户管理</a></li>
  File "/volumec/python_programe/python-exercise/ipmanager/venv/lib64/python3.6/site-packages/flask/helpers.py", line 370, in url_for
    return appctx.app.handle_url_build_error(error, endpoint, values)
  File "/volumec/python_programe/python-exercise/ipmanager/venv/lib64/python3.6/site-packages/flask/app.py", line 2216, in handle_url_build_error
    reraise(exc_type, exc_value, tb)
  File "/volumec/python_programe/python-exercise/ipmanager/venv/lib64/python3.6/site-packages/flask/_compat.py", line 39, in reraise
    raise value
  File "/volumec/python_programe/python-exercise/ipmanager/venv/lib64/python3.6/site-packages/flask/helpers.py", line 358, in url_for
    endpoint, values, method=method, force_external=external
  File "/volumec/python_programe/python-exercise/ipmanager/venv/lib64/python3.6/site-packages/werkzeug/routing.py", line 2179, in build
    raise BuildError(endpoint, values, method, self)
werkzeug.routing.BuildError: Could not build url for endpoint 'user_add'. Did you mean 'user_manager' instead?
2020-11-12 17:01:57,946 INFO: IpManager startup [in /volumec/python_programe/python-exercise/ipmanager/app/__init__.py:32]
2020-11-12 17:02:02,066 ERROR: Exception on /user_manager [GET] [in /volumec/python_programe/python-exercise/ipmanager/venv/lib64/python3.6/site-packages/flask/app.py:1892]
Traceback (most recent call last):
  File "/volumec/python_programe/python-exercise/ipmanager/venv/lib64/python3.6/site-packages/flask/app.py", line 2447, in wsgi_app
    response = self.full_dispatch_request()
  File "/volumec/python_programe/python-exercise/ipmanager/venv/lib64/python3.6/site-packages/flask/app.py", line 1952, in full_dispatch_request
    rv = self.handle_user_exception(e)
  File "/volumec/python_programe/python-exercise/ipmanager/venv/lib64/python3.6/site-packages/flask/app.py", line 1821, in handle_user_exception
    reraise(exc_type, exc_value, tb)
  File "/volumec/python_programe/python-exercise/ipmanager/venv/lib64/python3.6/site-packages/flask/_compat.py", line 39, in reraise
    raise value
  File "/volumec/python_programe/python-exercise/ipmanager/venv/lib64/python3.6/site-packages/flask/app.py", line 1950, in full_dispatch_request
    rv = self.dispatch_request()
  File "/volumec/python_programe/python-exercise/ipmanager/venv/lib64/python3.6/site-packages/flask/app.py", line 1936, in dispatch_request
    return self.view_functions[rule.endpoint](**req.view_args)
  File "/volumec/python_programe/python-exercise/ipmanager/app/routes.py", line 62, in user_manager
    page, app.config['USERS_PER_PAGE'], False)
NameError: name 'page' is not defined
2020-11-12 17:13:11,996 INFO: IpManager startup [in /volumec/python_programe/python-exercise/ipmanager/app/__init__.py:32]
2020-11-12 17:13:24,833 ERROR: Exception on /user_add [GET] [in /volumec/python_programe/python-exercise/ipmanager/venv/lib64/python3.6/site-packages/flask/app.py:1892]
Traceback (most recent call last):
  File "/volumec/python_programe/python-exercise/ipmanager/venv/lib64/python3.6/site-packages/flask/app.py", line 2447, in wsgi_app
    response = self.full_dispatch_request()
  File "/volumec/python_programe/python-exercise/ipmanager/venv/lib64/python3.6/site-packages/flask/app.py", line 1952, in full_dispatch_request
    rv = self.handle_user_exception(e)
  File "/volumec/python_programe/python-exercise/ipmanager/venv/lib64/python3.6/site-packages/flask/app.py", line 1821, in handle_user_exception
    reraise(exc_type, exc_value, tb)
  File "/volumec/python_programe/python-exercise/ipmanager/venv/lib64/python3.6/site-packages/flask/_compat.py", line 39, in reraise
    raise value
  File "/volumec/python_programe/python-exercise/ipmanager/venv/lib64/python3.6/site-packages/flask/app.py", line 1950, in full_dispatch_request
    rv = self.dispatch_request()
  File "/volumec/python_programe/python-exercise/ipmanager/venv/lib64/python3.6/site-packages/flask/app.py", line 1936, in dispatch_request
    return self.view_functions[rule.endpoint](**req.view_args)
  File "/volumec/python_programe/python-exercise/ipmanager/venv/lib64/python3.6/site-packages/flask_login/utils.py", line 272, in decorated_view
    return func(*args, **kwargs)
  File "/volumec/python_programe/python-exercise/ipmanager/app/routes.py", line 81, in user_add
    return render_template("user_manager.html", title='Home Page', users=users.items, next_url=next_url,
NameError: name 'users' is not defined
2020-11-12 17:16:11,073 INFO: IpManager startup [in /volumec/python_programe/python-exercise/ipmanager/app/__init__.py:32]
2020-11-12 17:20:15,542 INFO: IpManager startup [in /volumec/python_programe/python-exercise/ipmanager/app/__init__.py:32]
