2020-11-12 08:51:02,919 ERROR: Exception on / [GET] [in /volumec/python_programe/python-exercise/ipmanager/venv/lib64/python3.6/site-packages/flask/app.py:1892]
Traceback (most recent call last):
  File "/volumec/python_programe/python-exercise/ipmanager/venv/lib64/python3.6/site-packages/sqlalchemy/engine/base.py", line 1277, in _execute_context
    cursor, statement, parameters, context
  File "/volumec/python_programe/python-exercise/ipmanager/venv/lib64/python3.6/site-packages/sqlalchemy/engine/default.py", line 593, in do_execute
    cursor.execute(statement, parameters)
sqlite3.OperationalError: no such column: user.role

The above exception was the direct cause of the following exception:

Traceback (most recent call last):
  File "/volumec/python_programe/python-exercise/ipmanager/venv/lib64/python3.6/site-packages/flask/app.py", line 2447, in wsgi_app
    response = self.full_dispatch_request()
  File "/volumec/python_programe/python-exercise/ipmanager/venv/lib64/python3.6/site-packages/flask/app.py", line 1952, in full_dispatch_request
    rv = self.handle_user_exception(e)
  File "/volumec/python_programe/python-exercise/ipmanager/venv/lib64/python3.6/site-packages/flask/app.py", line 1821, in handle_user_exception
    reraise(exc_type, exc_value, tb)
  File "/volumec/python_programe/python-exercise/ipmanager/venv/lib64/python3.6/site-packages/flask/_compat.py", line 39, in reraise
    raise value
  File "/volumec/python_programe/python-exercise/ipmanager/venv/lib64/python3.6/site-packages/flask/app.py", line 1948, in full_dispatch_request
    rv = self.preprocess_request()
  File "/volumec/python_programe/python-exercise/ipmanager/venv/lib64/python3.6/site-packages/flask/app.py", line 2242, in preprocess_request
    rv = func()
  File "/volumec/python_programe/python-exercise/ipmanager/app/routes.py", line 150, in before_request
    if current_user.is_authenticated:
  File "/volumec/python_programe/python-exercise/ipmanager/venv/lib64/python3.6/site-packages/werkzeug/local.py", line 347, in __getattr__
    return getattr(self._get_current_object(), name)
  File "/volumec/python_programe/python-exercise/ipmanager/venv/lib64/python3.6/site-packages/werkzeug/local.py", line 306, in _get_current_object
    return self.__local()
  File "/volumec/python_programe/python-exercise/ipmanager/venv/lib64/python3.6/site-packages/flask_login/utils.py", line 26, in <lambda>
    current_user = LocalProxy(lambda: _get_user())
  File "/volumec/python_programe/python-exercise/ipmanager/venv/lib64/python3.6/site-packages/flask_login/utils.py", line 346, in _get_user
    current_app.login_manager._load_user()
  File "/volumec/python_programe/python-exercise/ipmanager/venv/lib64/python3.6/site-packages/flask_login/login_manager.py", line 318, in _load_user
    user = self._user_callback(user_id)
  File "/volumec/python_programe/python-exercise/ipmanager/app/models.py", line 63, in load_user
    return User.query.get(int(id))
  File "/volumec/python_programe/python-exercise/ipmanager/venv/lib64/python3.6/site-packages/sqlalchemy/orm/query.py", line 1018, in get
    return self._get_impl(ident, loading.load_on_pk_identity)
  File "/volumec/python_programe/python-exercise/ipmanager/venv/lib64/python3.6/site-packages/sqlalchemy/orm/query.py", line 1135, in _get_impl
    return db_load_fn(self, primary_key_identity)
  File "/volumec/python_programe/python-exercise/ipmanager/venv/lib64/python3.6/site-packages/sqlalchemy/orm/loading.py", line 286, in load_on_pk_identity
    return q.one()
  File "/volumec/python_programe/python-exercise/ipmanager/venv/lib64/python3.6/site-packages/sqlalchemy/orm/query.py", line 3490, in one
    ret = self.one_or_none()
  File "/volumec/python_programe/python-exercise/ipmanager/venv/lib64/python3.6/site-packages/sqlalchemy/orm/query.py", line 3459, in one_or_none
    ret = list(self)
  File "/volumec/python_programe/python-exercise/ipmanager/venv/lib64/python3.6/site-packages/sqlalchemy/orm/query.py", line 3535, in __iter__
    return self._execute_and_instances(context)
  File "/volumec/python_programe/python-exercise/ipmanager/venv/lib64/python3.6/site-packages/sqlalchemy/orm/query.py", line 3560, in _execute_and_instances
    result = conn.execute(querycontext.statement, self._params)
  File "/volumec/python_programe/python-exercise/ipmanager/venv/lib64/python3.6/site-packages/sqlalchemy/engine/base.py", line 1011, in execute
    return meth(self, multiparams, params)
  File "/volumec/python_programe/python-exercise/ipmanager/venv/lib64/python3.6/site-packages/sqlalchemy/sql/elements.py", line 298, in _execute_on_connection
    return connection._execute_clauseelement(self, multiparams, params)
  File "/volumec/python_programe/python-exercise/ipmanager/venv/lib64/python3.6/site-packages/sqlalchemy/engine/base.py", line 1130, in _execute_clauseelement
    distilled_params,
  File "/volumec/python_programe/python-exercise/ipmanager/venv/lib64/python3.6/site-packages/sqlalchemy/engine/base.py", line 1317, in _execute_context
    e, statement, parameters, cursor, context
  File "/volumec/python_programe/python-exercise/ipmanager/venv/lib64/python3.6/site-packages/sqlalchemy/engine/base.py", line 1511, in _handle_dbapi_exception
    sqlalchemy_exception, with_traceback=exc_info[2], from_=e
  File "/volumec/python_programe/python-exercise/ipmanager/venv/lib64/python3.6/site-packages/sqlalchemy/util/compat.py", line 182, in raise_
    raise exception
  File "/volumec/python_programe/python-exercise/ipmanager/venv/lib64/python3.6/site-packages/sqlalchemy/engine/base.py", line 1277, in _execute_context
    cursor, statement, parameters, context
  File "/volumec/python_programe/python-exercise/ipmanager/venv/lib64/python3.6/site-packages/sqlalchemy/engine/default.py", line 593, in do_execute
    cursor.execute(statement, parameters)
sqlalchemy.exc.OperationalError: (sqlite3.OperationalError) no such column: user.role
[SQL: SELECT user.id AS user_id, user.username AS user_username, user.email AS user_email, user.password_hash AS user_password_hash, user.role AS user_role 
FROM user 
WHERE user.id = ?]
[parameters: (3,)]
(Background on this error at: http://sqlalche.me/e/13/e3q8)
